Workbook
Name InspectorName: 'الإعدادات'!$B$3
Name OrgName: 'الإعدادات'!$B$4
Name SectorName: 'الإعدادات'!$B$5
Name PhotoDir: 'الإعدادات'!$B$6
Name AreaHdr: 'الإعدادات'!$A$11:$J$11
Name SitesTop: 'الإعدادات'!$A$12
Name AreaList: OFFSET('الإعدادات'!$A$11,0,0,1,COUNTA('الإعدادات'!$A$11:$J$11))
Name TypeList: OFFSET('الإعدادات'!$L$12,0,0,COUNTA('الإعدادات'!$L$12:$L$26),1)
Name ActionList: 'الإعدادات'!$N$12:$N$14
Name MonthList: 'الإعدادات'!$P$12:$P$23
Name PeriodList: 'الإعدادات'!$R$12:$R$18
Name PeriodTbl: 'الإعدادات'!$R$12:$T$18
Name L_Date: 'سجل الزيارات'!$B$5:$B$1504
Name L_Area: 'سجل الزيارات'!$C$5:$C$1504
Name L_Site: 'سجل الزيارات'!$D$5:$D$1504
Name L_Arr: 'سجل الزيارات'!$E$5:$E$1504
Name L_Type: 'سجل الزيارات'!$G$5:$G$1504
Name L_Desc: 'سجل الزيارات'!$H$5:$H$1504
Name L_Act: 'سجل الزيارات'!$I$5:$I$1504
Name L_Pics: 'سجل الزيارات'!$J$5:$J$1504
Name L_Month: 'سجل الزيارات'!$Q$5:$Q$1504
Name L_Year: 'سجل الزيارات'!$R$5:$R$1504
Name L_Week: 'سجل الزيارات'!$S$5:$S$1504
Name L_NewVisit: 'سجل الزيارات'!$T$5:$T$1504
Name L_NewArea: 'سجل الزيارات'!$U$5:$U$1504
Name L_Obs: 'سجل الزيارات'!$V$5:$V$1504
Name L_Viol: 'سجل الزيارات'!$W$5:$W$1504
Name L_WIdx: 'سجل الزيارات'!$X$5:$X$1504
Name WkStart: 'التقرير الأسبوعي'!$D$5

Sheet طريقة الاستخدام
B1: سجل التفتيش البيئي — طريقة الاستخدام
B3: فكرة الملف
B4: ١ | C4: كل صف في «سجل الزيارات» = مشاهدة واحدة في موقع واحد. لو في الموقع أكثر من مشاهدة، سجّل كل وحدة في صف بنفس التاريخ والموقع، والملف يحسبها زيارة واحدة تلقائيًا.
B5: ٢ | C5: لو زرت موقع وما لقيت شيء، سجّل صف واحد ونوع المشاهدة «لا توجد مشاهدات» والإجراء «لا يوجد».
B6: ٣ | C6: التقارير الأسبوعية والشهرية والدورية تُحسب كلها تلقائيًا من السجل — ما تكتب فيها شيء غير الخانات الصفراء (التاريخ أو الشهر أو الفترة).
B7: الإدخال
B8: ٤ | C8: عبّئ الأعمدة الخضراء: التاريخ، المنطقة، الموقع، الأوقات، نوع المشاهدة، الوصف، الإجراء، عدد الصور، الإحداثيات، الملاحظات.
B9: ٥ | C9: المنطقة والموقع ونوع المشاهدة والإجراء كلها قوائم تختار منها. قائمة المواقع تتغير حسب المنطقة اللي اخترتها.
B10: ٦ | C10: من التطبيق: اضغط «تصدير»، افتح ملف الإكسل اللي يطلعه، انسخ الصفوف، والصقها في أول صف فاضي في السجل ابتداءً من عمود «التاريخ» (لصق قيم فقط).
B11: الصور
B12: ٧ | C12: الصور ما تنحط داخل الإكسل عشان الملف ما يثقل. تكون في فولدر اسمه «الصور» بجانب ملف الإكسل، وداخله فولدر لكل زيارة باسم: التاريخ_الموقع (مثال: 2026-10-26_الثروانية).
B13: ٨ | C13: عمود «الصور» في السجل فيه رابط يفتح فولدر الزيارة مباشرة، وعمود «الخريطة» يفتح موقع الزيارة على خرائط جوجل.
B14: الإعدادات
B15: ٩ | C15: في شيت «الإعدادات» تقدر تغيّر اسم المفتش والجهة، وتضيف مواقع أو مناطق أو أنواع مشاهدات جديدة في الخانات الصفراء — وتظهر فورًا في القوائم والتقارير.
B16: قبل البدء
B17: ١٠ | C17: في السجل ٥ صفوف تجريبية ملوّنة بالبنفسجي عشان تشوف شكل التقارير. احذف محتواها (من عمود التاريخ إلى الملاحظات) قبل ما تبدأ التسجيل الفعلي.
B19: مفتاح الألوان:
C20: خانة تكتب فيها أنت
C21: عمود إدخال في السجل
C22: عمود يُحسب تلقائيًا

Sheet سجل الزيارات
A1: سجل الزيارات التفتيشية
A2: الأعمدة الخضراء تُعبّأ (يدويًا أو بلصق ما يصدّره التطبيق ابتداءً من عمود التاريخ). الأعمدة الرمادية تُحسب تلقائيًا ولا تحتاج تعديل.
Q3: أعمدة مساعدة — لا تعدّلها
A4: م | B4: التاريخ | C4: المنطقة | D4: الموقع / المحضر | E4: وقت الوصول | F4: وقت المغادرة | G4: نوع المشاهدة | H4: وصف المشاهدة | I4: الإجراء | J4: عدد الصور | K4: خط العرض | L4: خط الطول | M4: ملاحظات | N4: اليوم | O4: الخريطة | P4: الصور | Q4: الشهر | R4: السنة | S4: بداية الأسبوع | T4: زيارة جديدة | U4: منطقة جديدة باليوم | V4: مشاهدة | W4: مخالفة | X4: ترتيب الأسبوع
A5: =IF($B5="","",ROW()-4) | N5: =IF($B5="","",CHOOSE(WEEKDAY($B5),"الأحد","الاثنين","الثلاثاء","الأربعاء","الخميس","الجمعة","السبت")) | O5: =IF(OR($K5="",$L5=""),"",HYPERLINK("https://maps.google.com/?q="&$K5&","&$L5,"عرض الموقع")) | P5: =IF(OR($B5="",N($J5)=0),"",HYPERLINK(PhotoDir&"/"&YEAR($B5)&"-"&TEXT(MONTH($B5),"00")&"-"&TEXT(DAY($B5),"00")&"_"&$D5,"فتح الصور ("&$J5&")")) | Q5: =IF($B5="","",MONTH($B5)) | R5: =IF($B5="","",YEAR($B5)) | S5: =IF($B5="","",$B5-WEEKDAY($B5,3)) | T5: =IF($B5="",0,IF(COUNTIFS($B$5:$B5,$B5,$D$5:$D5,$D5)=1,1,0)) | U5: =IF($B5="",0,IF(COUNTIFS($B$5:$B5,$B5,$C$5:$C5,$C5)=1,1,0)) | V5: =IF(OR($B5="",$G5="",$G5="لا توجد مشاهدات"),0,1) | W5: =IF(AND($B5<>"",$I5="تم تحرير مخالفة"),1,0) | X5: =IF($B5="","",IF($S5=WkStart,COUNTIF($S$5:$S5,WkStart),""))
A6: =IF($B6="","",ROW()-4) | N6: =IF($B6="","",CHOOSE(WEEKDAY($B6),"الأحد","الاثنين","الثلاثاء","الأربعاء","الخميس","الجمعة","السبت")) | O6: =IF(OR($K6="",$L6=""),"",HYPERLINK("https://maps.google.com/?q="&$K6&","&$L6,"عرض الموقع")) | P6: =IF(OR($B6="",N($J6)=0),"",HYPERLINK(PhotoDir&"/"&YEAR($B6)&"-"&TEXT(MONTH($B6),"00")&"-"&TEXT(DAY($B6),"00")&"_"&$D6,"فتح الصور ("&$J6&")")) | Q6: =IF($B6="","",MONTH($B6)) | R6: =IF($B6="","",YEAR($B6)) | S6: =IF($B6="","",$B6-WEEKDAY($B6,3)) | T6: =IF($B6="",0,IF(COUNTIFS($B$5:$B6,$B6,$D$5:$D6,$D6)=1,1,0)) | U6: =IF($B6="",0,IF(COUNTIFS($B$5:$B6,$B6,$C$5:$C6,$C6)=1,1,0)) | V6: =IF(OR($B6="",$G6="",$G6="لا توجد مشاهدات"),0,1) | W6: =IF(AND($B6<>"",$I6="تم تحرير مخالفة"),1,0) | X6: =IF($B6="","",IF($S6=WkStart,COUNTIF($S$5:$S6,WkStart),""))
A7: =IF($B7="","",ROW()-4) | N7: =IF($B7="","",CHOOSE(WEEKDAY($B7),"الأحد","الاثنين","الثلاثاء","الأربعاء","الخميس","الجمعة","السبت")) | O7: =IF(OR($K7="",$L7=""),"",HYPERLINK("https://maps.google.com/?q="&$K7&","&$L7,"عرض الموقع")) | P7: =IF(OR($B7="",N($J7)=0),"",HYPERLINK(PhotoDir&"/"&YEAR($B7)&"-"&TEXT(MONTH($B7),"00")&"-"&TEXT(DAY($B7),"00")&"_"&$D7,"فتح الصور ("&$J7&")")) | Q7: =IF($B7="","",MONTH($B7)) | R7: =IF($B7="","",YEAR($B7)) | S7: =IF($B7="","",$B7-WEEKDAY($B7,3)) | T7: =IF($B7="",0,IF(COUNTIFS($B$5:$B7,$B7,$D$5:$D7,$D7)=1,1,0)) | U7: =IF($B7="",0,IF(COUNTIFS($B$5:$B7,$B7,$C$5:$C7,$C7)=1,1,0)) | V7: =IF(OR($B7="",$G7="",$G7="لا توجد مشاهدات"),0,1) | W7: =IF(AND($B7<>"",$I7="تم تحرير مخالفة"),1,0) | X7: =IF($B7="","",IF($S7=WkStart,COUNTIF($S$5:$S7,WkStart),""))
A8: =IF($B8="","",ROW()-4) | N8: =IF($B8="","",CHOOSE(WEEKDAY($B8),"الأحد","الاثنين","الثلاثاء","الأربعاء","الخميس","الجمعة","السبت")) | O8: =IF(OR($K8="",$L8=""),"",HYPERLINK("https://maps.google.com/?q="&$K8&","&$L8,"عرض الموقع")) | P8: =IF(OR($B8="",N($J8)=0),"",HYPERLINK(PhotoDir&"/"&YEAR($B8)&"-"&TEXT(MONTH($B8),"00")&"-"&TEXT(DAY($B8),"00")&"_"&$D8,"فتح الصور ("&$J8&")")) | Q8: =IF($B8="","",MONTH($B8)) | R8: =IF($B8="","",YEAR($B8)) | S8: =IF($B8="","",$B8-WEEKDAY($B8,3)) | T8: =IF($B8="",0,IF(COUNTIFS($B$5:$B8,$B8,$D$5:$D8,$D8)=1,1,0)) | U8: =IF($B8="",0,IF(COUNTIFS($B$5:$B8,$B8,$C$5:$C8,$C8)=1,1,0)) | V8: =IF(OR($B8="",$G8="",$G8="لا توجد مشاهدات"),0,1) | W8: =IF(AND($B8<>"",$I8="تم تحرير مخالفة"),1,0) | X8: =IF($B8="","",IF($S8=WkStart,COUNTIF($S$5:$S8,WkStart),""))
A9: =IF($B9="","",ROW()-4) | N9: =IF($B9="","",CHOOSE(WEEKDAY($B9),"الأحد","الاثنين","الثلاثاء","الأربعاء","الخميس","الجمعة","السبت")) | O9: =IF(OR($K9="",$L9=""),"",HYPERLINK("https://maps.google.com/?q="&$K9&","&$L9,"عرض الموقع")) | P9: =IF(OR($B9="",N($J9)=0),"",HYPERLINK(PhotoDir&"/"&YEAR($B9)&"-"&TEXT(MONTH($B9),"00")&"-"&TEXT(DAY($B9),"00")&"_"&$D9,"فتح الصور ("&$J9&")")) | Q9: =IF($B9="","",MONTH($B9)) | R9: =IF($B9="","",YEAR($B9)) | S9: =IF($B9="","",$B9-WEEKDAY($B9,3)) | T9: =IF($B9="",0,IF(COUNTIFS($B$5:$B9,$B9,$D$5:$D9,$D9)=1,1,0)) | U9: =IF($B9="",0,IF(COUNTIFS($B$5:$B9,$B9,$C$5:$C9,$C9)=1,1,0)) | V9: =IF(OR($B9="",$G9="",$G9="لا توجد مشاهدات"),0,1) | W9: =IF(AND($B9<>"",$I9="تم تحرير مخالفة"),1,0) | X9: =IF($B9="","",IF($S9=WkStart,COUNTIF($S$5:$S9,WkStart),""))
A10: =IF($B10="","",ROW()-4) | N10: =IF($B10="","",CHOOSE(WEEKDAY($B10),"الأحد","الاثنين","الثلاثاء","الأربعاء","الخميس","الجمعة","السبت")) | O10: =IF(OR($K10="",$L10=""),"",HYPERLINK("https://maps.google.com/?q="&$K10&","&$L10,"عرض الموقع")) | P10: =IF(OR($B10="",N($J10)=0),"",HYPERLINK(PhotoDir&"/"&YEAR($B10)&"-"&TEXT(MONTH($B10),"00")&"-"&TEXT(DAY($B10),"00")&"_"&$D10,"فتح الصور ("&$J10&")")) | Q10: =IF($B10="","",MONTH($B10)) | R10: =IF($B10="","",YEAR($B10)) | S10: =IF($B10="","",$B10-WEEKDAY($B10,3)) | T10: =IF($B10="",0,IF(COUNTIFS($B$5:$B10,$B10,$D$5:$D10,$D10)=1,1,0)) | U10: =IF($B10="",0,IF(COUNTIFS($B$5:$B10,$B10,$C$5:$C10,$C10)=1,1,0)) | V10: =IF(OR($B10="",$G10="",$G10="لا توجد مشاهدات"),0,1) | W10: =IF(AND($B10<>"",$I10="تم تحرير مخالفة"),1,0) | X10: =IF($B10="","",IF($S10=WkStart,COUNTIF($S$5:$S10,WkStart),""))
A11: =IF($B11="","",ROW()-4) | N11: =IF($B11="","",CHOOSE(WEEKDAY($B11),"الأحد","الاثنين","الثلاثاء","الأربعاء","الخميس","الجمعة","السبت")) | O11: =IF(OR($K11="",$L11=""),"",HYPERLINK("https://maps.google.com/?q="&$K11&","&$L11,"عرض الموقع")) | P11: =IF(OR($B11="",N($J11)=0),"",HYPERLINK(PhotoDir&"/"&YEAR($B11)&"-"&TEXT(MONTH($B11),"00")&"-"&TEXT(DAY($B11),"00")&"_"&$D11,"فتح الصور ("&$J11&")")) | Q11: =IF($B11="","",MONTH($B11)) | R11: =IF($B11="","",YEAR($B11)) | S11: =IF($B11="","",$B11-WEEKDAY($B11,3)) | T11: =IF($B11="",0,IF(COUNTIFS($B$5:$B11,$B11,$D$5:$D11,$D11)=1,1,0)) | U11: =IF($B11="",0,IF(COUNTIFS($B$5:$B11,$B11,$C$5:$C11,$C11)=1,1,0)) | V11: =IF(OR($B11="",$G11="",$G11="لا توجد مشاهدات"),0,1) | W11: =IF(AND($B11<>"",$I11="تم تحرير مخالفة"),1,0) | X11: =IF($B11="","",IF($S11=WkStart,COUNTIF($S$5:$S11,WkStart),""))
A12: =IF($B12="","",ROW()-4) | N12: =IF($B12="","",CHOOSE(WEEKDAY($B12),"الأحد","الاثنين","الثلاثاء","الأربعاء","الخميس","الجمعة","السبت")) | O12: =IF(OR($K12="",$L12=""),"",HYPERLINK("https://maps.google.com/?q="&$K12&","&$L12,"عرض الموقع")) | P12: =IF(OR($B12="",N($J12)=0),"",HYPERLINK(PhotoDir&"/"&YEAR($B12)&"-"&TEXT(MONTH($B12),"00")&"-"&TEXT(DAY($B12),"00")&"_"&$D12,"فتح الصور ("&$J12&")")) | Q12: =IF($B12="","",MONTH($B12)) | R12: =IF($B12="","",YEAR($B12)) | S12: =IF($B12="","",$B12-WEEKDAY($B12,3)) | T12: =IF($B12="",0,IF(COUNTIFS($B$5:$B12,$B12,$D$5:$D12,$D12)=1,1,0)) | U12: =IF($B12="",0,IF(COUNTIFS($B$5:$B12,$B12,$C$5:$C12,$C12)=1,1,0)) | V12: =IF(OR($B12="",$G12="",$G12="لا توجد مشاهدات"),0,1) | W12: =IF(AND($B12<>"",$I12="تم تحرير مخالفة"),1,0) | X12: =IF($B12="","",IF($S12=WkStart,COUNTIF($S$5:$S12,WkStart),""))
A13: =IF($B13="","",ROW()-4) | N13: =IF($B13="","",CHOOSE(WEEKDAY($B13),"الأحد","الاثنين","الثلاثاء","الأربعاء","الخميس","الجمعة","السبت")) | O13: =IF(OR($K13="",$L13=""),"",HYPERLINK("https://maps.google.com/?q="&$K13&","&$L13,"عرض الموقع")) | P13: =IF(OR($B13="",N($J13)=0),"",HYPERLINK(PhotoDir&"/"&YEAR($B13)&"-"&TEXT(MONTH($B13),"00")&"-"&TEXT(DAY($B13),"00")&"_"&$D13,"فتح الصور ("&$J13&")")) | Q13: =IF($B13="","",MONTH($B13)) | R13: =IF($B13="","",YEAR($B13)) | S13: =IF($B13="","",$B13-WEEKDAY($B13,3)) | T13: =IF($B13="",0,IF(COUNTIFS($B$5:$B13,$B13,$D$5:$D13,$D13)=1,1,0)) | U13: =IF($B13="",0,IF(COUNTIFS($B$5:$B13,$B13,$C$5:$C13,$C13)=1,1,0)) | V13: =IF(OR($B13="",$G13="",$G13="لا توجد مشاهدات"),0,1) | W13: =IF(AND($B13<>"",$I13="تم تحرير مخالفة"),1,0) | X13: =IF($B13="","",IF($S13=WkStart,COUNTIF($S$5:$S13,WkStart),""))
A14: =IF($B14="","",ROW()-4) | N14: =IF($B14="","",CHOOSE(WEEKDAY($B14),"الأحد","الاثنين","الثلاثاء","الأربعاء","الخميس","الجمعة","السبت")) | O14: =IF(OR($K14="",$L14=""),"",HYPERLINK("https://maps.google.com/?q="&$K14&","&$L14,"عرض الموقع")) | P14: =IF(OR($B14="",N($J14)=0),"",HYPERLINK(PhotoDir&"/"&YEAR($B14)&"-"&TEXT(MONTH($B14),"00")&"-"&TEXT(DAY($B14),"00")&"_"&$D14,"فتح الصور ("&$J14&")")) | Q14: =IF($B14="","",MONTH($B14)) | R14: =IF($B14="","",YEAR($B14)) | S14: =IF($B14="","",$B14-WEEKDAY($B14,3)) | T14: =IF($B14="",0,IF(COUNTIFS($B$5:$B14,$B14,$D$5:$D14,$D14)=1,1,0)) | U14: =IF($B14="",0,IF(COUNTIFS($B$5:$B14,$B14,$C$5:$C14,$C14)=1,1,0)) | V14: =IF(OR($B14="",$G14="",$G14="لا توجد مشاهدات"),0,1) | W14: =IF(AND($B14<>"",$I14="تم تحرير مخالفة"),1,0) | X14: =IF($B14="","",IF($S14=WkStart,COUNTIF($S$5:$S14,WkStart),""))
A15: =IF($B15="","",ROW()-4) | N15: =IF($B15="","",CHOOSE(WEEKDAY($B15),"الأحد","الاثنين","الثلاثاء","الأربعاء","الخميس","الجمعة","السبت")) | O15: =IF(OR($K15="",$L15=""),"",HYPERLINK("https://maps.google.com/?q="&$K15&","&$L15,"عرض الموقع")) | P15: =IF(OR($B15="",N($J15)=0),"",HYPERLINK(PhotoDir&"/"&YEAR($B15)&"-"&TEXT(MONTH($B15),"00")&"-"&TEXT(DAY($B15),"00")&"_"&$D15,"فتح الصور ("&$J15&")")) | Q15: =IF($B15="","",MONTH($B15)) | R15: =IF($B15="","",YEAR($B15)) | S15: =IF($B15="","",$B15-WEEKDAY($B15,3)) | T15: =IF($B15="",0,IF(COUNTIFS($B$5:$B15,$B15,$D$5:$D15,$D15)=1,1,0)) | U15: =IF($B15="",0,IF(COUNTIFS($B$5:$B15,$B15,$C$5:$C15,$C15)=1,1,0)) | V15: =IF(OR($B15="",$G15="",$G15="لا توجد مشاهدات"),0,1) | W15: =IF(AND($B15<>"",$I15="تم تحرير مخالفة"),1,0) | X15: =IF($B15="","",IF($S15=WkStart,COUNTIF($S$5:$S15,WkStart),""))
A16: =IF($B16="","",ROW()-4) | N16: =IF($B16="","",CHOOSE(WEEKDAY($B16),"الأحد","الاثنين","الثلاثاء","الأربعاء","الخميس","الجمعة","السبت")) | O16: =IF(OR($K16="",$L16=""),"",HYPERLINK("https://maps.google.com/?q="&$K16&","&$L16,"عرض الموقع")) | P16: =IF(OR($B16="",N($J16)=0),"",HYPERLINK(PhotoDir&"/"&YEAR($B16)&"-"&TEXT(MONTH($B16),"00")&"-"&TEXT(DAY($B16),"00")&"_"&$D16,"فتح الصور ("&$J16&")")) | Q16: =IF($B16="","",MONTH($B16)) | R16: =IF($B16="","",YEAR($B16)) | S16: =IF($B16="","",$B16-WEEKDAY($B16,3)) | T16: =IF($B16="",0,IF(COUNTIFS($B$5:$B16,$B16,$D$5:$D16,$D16)=1,1,0)) | U16: =IF($B16="",0,IF(COUNTIFS($B$5:$B16,$B16,$C$5:$C16,$C16)=1,1,0)) | V16: =IF(OR($B16="",$G16="",$G16="لا توجد مشاهدات"),0,1) | W16: =IF(AND($B16<>"",$I16="تم تحرير مخالفة"),1,0) | X16: =IF($B16="","",IF($S16=WkStart,COUNTIF($S$5:$S16,WkStart),""))
... A1504: =IF($B1504="","",ROW()-4) | N1504: =IF($B1504="","",CHOOSE(WEEKDAY($B1504),"الأحد","الاثنين","الثلاثاء","الأربعاء","الخميس","الجمعة","السبت")) | O1504: =IF(OR($K1504="",$L1504=""),"",HYPERLINK("https://maps.google.com/?q="&$K1504&","&$L1504,"عرض الموقع")) | P1504: =IF(OR($B1504="",N($J1504)=0),"",HYPERLINK(PhotoDir&"/"&YEAR($B1504)&"-"&TEXT(MONTH($B1504),"00")&"-"&TEXT(DAY($B1504),"00")&"_"&$D1504,"فتح الصور ("&$J1504&")")) | Q1504: =IF($B1504="","",MONTH($B1504)) | R1504: =IF($B1504="","",YEAR($B1504)) | S1504: =IF($B1504="","",$B1504-WEEKDAY($B1504,3)) | T1504: =IF($B1504="",0,IF(COUNTIFS($B$5:$B1504,$B1504,$D$5:$D1504,$D1504)=1,1,0)) | U1504: =IF($B1504="",0,IF(COUNTIFS($B$5:$B1504,$B1504,$C$5:$C1504,$C1504)=1,1,0)) | V1504: =IF(OR($B1504="",$G1504="",$G1504="لا توجد مشاهدات"),0,1) | W1504: =IF(AND($B1504<>"",$I1504="تم تحرير مخالفة"),1,0) | X1504: =IF($B1504="","",IF($S1504=WkStart,COUNTIF($S$5:$S1504,WkStart),""))

Sheet التقرير الأسبوعي
B1: التقرير الأسبوعي للتفتيش البيئي
B2: =OrgName&" | "&SectorName
B4: اكتب أي تاريخ من الأسبوع: | D4: 46323 | E4: ← يحسب الملف بداية ونهاية الأسبوع تلقائيًا
B5: الفترة: | D5: =D4-WEEKDAY(D4,3) | E5: ="من الاثنين "&TEXT(D5,"yyyy/mm/dd")&" إلى الجمعة "&TEXT(D5+4,"yyyy/mm/dd") | F5: ="الأسبوع رقم "&WEEKNUM(D5,2)
B6: المفتش: | D6: =InspectorName
B8: الزيارات | D8: المشاهدات البيئية | E8: المخالفات المحررة | F8: مشاهدات دون مخالف | H8: زيارات بلا مشاهدات
B9: =SUMIFS(L_NewVisit,L_Week,WkStart) | D9: =SUMIFS(L_Obs,L_Week,WkStart) | E9: =SUMIFS(L_Viol,L_Week,WkStart) | F9: =COUNTIFS(L_Week,WkStart,L_Act,"مشاهدة فقط") | H9: =COUNTIFS(L_Week,WkStart,L_Type,"لا توجد مشاهدات")
B11: ملخص أيام الأسبوع
B12: اليوم | C12: التاريخ | D12: المناطق | E12: المواقع المزارة | F12: الزيارات | G12: المشاهدات | H12: المخالفات | I12: دون مخالف
B13: الاثنين | C13: =WkStart+0 | D13: {=_xlfn.TEXTJOIN("، ",TRUE,IF((L_Date=C13)*(L_NewArea=1),L_Area,""))} | E13: {=_xlfn.TEXTJOIN("، ",TRUE,IF((L_Date=C13)*(L_NewVisit=1),L_Site,""))} | F13: =SUMIFS(L_NewVisit,L_Date,C13) | G13: =SUMIFS(L_Obs,L_Date,C13) | H13: =SUMIFS(L_Viol,L_Date,C13) | I13: =COUNTIFS(L_Date,C13,L_Act,"مشاهدة فقط")
B14: الثلاثاء | C14: =WkStart+1 | D14: {=_xlfn.TEXTJOIN("، ",TRUE,IF((L_Date=C14)*(L_NewArea=1),L_Area,""))} | E14: {=_xlfn.TEXTJOIN("، ",TRUE,IF((L_Date=C14)*(L_NewVisit=1),L_Site,""))} | F14: =SUMIFS(L_NewVisit,L_Date,C14) | G14: =SUMIFS(L_Obs,L_Date,C14) | H14: =SUMIFS(L_Viol,L_Date,C14) | I14: =COUNTIFS(L_Date,C14,L_Act,"مشاهدة فقط")
B15: الأربعاء | C15: =WkStart+2 | D15: {=_xlfn.TEXTJOIN("، ",TRUE,IF((L_Date=C15)*(L_NewArea=1),L_Area,""))} | E15: {=_xlfn.TEXTJOIN("، ",TRUE,IF((L_Date=C15)*(L_NewVisit=1),L_Site,""))} | F15: =SUMIFS(L_NewVisit,L_Date,C15) | G15: =SUMIFS(L_Obs,L_Date,C15) | H15: =SUMIFS(L_Viol,L_Date,C15) | I15: =COUNTIFS(L_Date,C15,L_Act,"مشاهدة فقط")
B16: الخميس | C16: =WkStart+3 | D16: {=_xlfn.TEXTJOIN("، ",TRUE,IF((L_Date=C16)*(L_NewArea=1),L_Area,""))} | E16: {=_xlfn.TEXTJOIN("، ",TRUE,IF((L_Date=C16)*(L_NewVisit=1),L_Site,""))} | F16: =SUMIFS(L_NewVisit,L_Date,C16) | G16: =SUMIFS(L_Obs,L_Date,C16) | H16: =SUMIFS(L_Viol,L_Date,C16) | I16: =COUNTIFS(L_Date,C16,L_Act,"مشاهدة فقط")
B17: الجمعة | C17: =WkStart+4 | D17: {=_xlfn.TEXTJOIN("، ",TRUE,IF((L_Date=C17)*(L_NewArea=1),L_Area,""))} | E17: {=_xlfn.TEXTJOIN("، ",TRUE,IF((L_Date=C17)*(L_NewVisit=1),L_Site,""))} | F17: =SUMIFS(L_NewVisit,L_Date,C17) | G17: =SUMIFS(L_Obs,L_Date,C17) | H17: =SUMIFS(L_Viol,L_Date,C17) | I17: =COUNTIFS(L_Date,C17,L_Act,"مشاهدة فقط")
B18: الإجمالي | F18: =SUM(F13:F17) | G18: =SUM(G13:G17) | H18: =SUM(H13:H17) | I18: =SUM(I13:I17)
B20: المشاهدات حسب النوع
B21: نوع المشاهدة | F21: العدد | G21: مخالفة محررة | H21: دون مخالف | I21: النسبة
B22: =IF(INDEX('الإعدادات'!$L$12:$L$26,1)="","",INDEX('الإعدادات'!$L$12:$L$26,1)) | F22: =IF($B22="","",COUNTIFS(L_Week,WkStart,L_Type,$B22)) | G22: =IF($B22="","",COUNTIFS(L_Week,WkStart,L_Type,$B22,L_Act,"تم تحرير مخالفة")) | H22: =IF($B22="","",COUNTIFS(L_Week,WkStart,L_Type,$B22,L_Act,"مشاهدة فقط")) | I22: =IF(OR($B22="",SUM($F$22:$F$31)=0),"",F22/SUM($F$22:$F$31))
B23: =IF(INDEX('الإعدادات'!$L$12:$L$26,2)="","",INDEX('الإعدادات'!$L$12:$L$26,2)) | F23: =IF($B23="","",COUNTIFS(L_Week,WkStart,L_Type,$B23)) | G23: =IF($B23="","",COUNTIFS(L_Week,WkStart,L_Type,$B23,L_Act,"تم تحرير مخالفة")) | H23: =IF($B23="","",COUNTIFS(L_Week,WkStart,L_Type,$B23,L_Act,"مشاهدة فقط")) | I23: =IF(OR($B23="",SUM($F$22:$F$31)=0),"",F23/SUM($F$22:$F$31))
B24: =IF(INDEX('الإعدادات'!$L$12:$L$26,3)="","",INDEX('الإعدادات'!$L$12:$L$26,3)) | F24: =IF($B24="","",COUNTIFS(L_Week,WkStart,L_Type,$B24)) | G24: =IF($B24="","",COUNTIFS(L_Week,WkStart,L_Type,$B24,L_Act,"تم تحرير مخالفة")) | H24: =IF($B24="","",COUNTIFS(L_Week,WkStart,L_Type,$B24,L_Act,"مشاهدة فقط")) | I24: =IF(OR($B24="",SUM($F$22:$F$31)=0),"",F24/SUM($F$22:$F$31))
B25: =IF(INDEX('الإعدادات'!$L$12:$L$26,4)="","",INDEX('الإعدادات'!$L$12:$L$26,4)) | F25: =IF($B25="","",COUNTIFS(L_Week,WkStart,L_Type,$B25)) | G25: =IF($B25="","",COUNTIFS(L_Week,WkStart,L_Type,$B25,L_Act,"تم تحرير مخالفة")) | H25: =IF($B25="","",COUNTIFS(L_Week,WkStart,L_Type,$B25,L_Act,"مشاهدة فقط")) | I25: =IF(OR($B25="",SUM($F$22:$F$31)=0),"",F25/SUM($F$22:$F$31))
B26: =IF(INDEX('الإعدادات'!$L$12:$L$26,5)="","",INDEX('الإعدادات'!$L$12:$L$26,5)) | F26: =IF($B26="","",COUNTIFS(L_Week,WkStart,L_Type,$B26)) | G26: =IF($B26="","",COUNTIFS(L_Week,WkStart,L_Type,$B26,L_Act,"تم تحرير مخالفة")) | H26: =IF($B26="","",COUNTIFS(L_Week,WkStart,L_Type,$B26,L_Act,"مشاهدة فقط")) | I26: =IF(OR($B26="",SUM($F$22:$F$31)=0),"",F26/SUM($F$22:$F$31))
B27: =IF(INDEX('الإعدادات'!$L$12:$L$26,6)="","",INDEX('الإعدادات'!$L$12:$L$26,6)) | F27: =IF($B27="","",COUNTIFS(L_Week,WkStart,L_Type,$B27)) | G27: =IF($B27="","",COUNTIFS(L_Week,WkStart,L_Type,$B27,L_Act,"تم تحرير مخالفة")) | H27: =IF($B27="","",COUNTIFS(L_Week,WkStart,L_Type,$B27,L_Act,"مشاهدة فقط")) | I27: =IF(OR($B27="",SUM($F$22:$F$31)=0),"",F27/SUM($F$22:$F$31))
B28: =IF(INDEX('الإعدادات'!$L$12:$L$26,7)="","",INDEX('الإعدادات'!$L$12:$L$26,7)) | F28: =IF($B28="","",COUNTIFS(L_Week,WkStart,L_Type,$B28)) | G28: =IF($B28="","",COUNTIFS(L_Week,WkStart,L_Type,$B28,L_Act,"تم تحرير مخالفة")) | H28: =IF($B28="","",COUNTIFS(L_Week,WkStart,L_Type,$B28,L_Act,"مشاهدة فقط")) | I28: =IF(OR($B28="",SUM($F$22:$F$31)=0),"",F28/SUM($F$22:$F$31))
B29: =IF(INDEX('الإعدادات'!$L$12:$L$26,8)="","",INDEX('الإعدادات'!$L$12:$L$26,8)) | F29: =IF($B29="","",COUNTIFS(L_Week,WkStart,L_Type,$B29)) | G29: =IF($B29="","",COUNTIFS(L_Week,WkStart,L_Type,$B29,L_Act,"تم تحرير مخالفة")) | H29: =IF($B29="","",COUNTIFS(L_Week,WkStart,L_Type,$B29,L_Act,"مشاهدة فقط")) | I29: =IF(OR($B29="",SUM($F$22:$F$31)=0),"",F29/SUM($F$22:$F$31))
B30: =IF(INDEX('الإعدادات'!$L$12:$L$26,9)="","",INDEX('الإعدادات'!$L$12:$L$26,9)) | F30: =IF($B30="","",COUNTIFS(L_Week,WkStart,L_Type,$B30)) | G30: =IF($B30="","",COUNTIFS(L_Week,WkStart,L_Type,$B30,L_Act,"تم تحرير مخالفة")) | H30: =IF($B30="","",COUNTIFS(L_Week,WkStart,L_Type,$B30,L_Act,"مشاهدة فقط")) | I30: =IF(OR($B30="",SUM($F$22:$F$31)=0),"",F30/SUM($F$22:$F$31))
B31: =IF(INDEX('الإعدادات'!$L$12:$L$26,10)="","",INDEX('الإعدادات'!$L$12:$L$26,10)) | F31: =IF($B31="","",COUNTIFS(L_Week,WkStart,L_Type,$B31)) | G31: =IF($B31="","",COUNTIFS(L_Week,WkStart,L_Type,$B31,L_Act,"تم تحرير مخالفة")) | H31: =IF($B31="","",COUNTIFS(L_Week,WkStart,L_Type,$B31,L_Act,"مشاهدة فقط")) | I31: =IF(OR($B31="",SUM($F$22:$F$31)=0),"",F31/SUM($F$22:$F$31))
B33: تفاصيل زيارات الأسبوع
B34: م | C34: التاريخ | D34: الموقع | E34: الوصف | F34: نوع المشاهدة | G34: الإجراء | H34: وقت الوصول | I34: الصور
B35: =IF(ISNUMBER(MATCH(1,L_WIdx,0)),1,"") | C35: =IF($B35="","",INDEX(L_Date,MATCH(1,L_WIdx,0))) | D35: =IF($B35="","",INDEX(L_Area,MATCH(1,L_WIdx,0))&" - "&INDEX(L_Site,MATCH(1,L_WIdx,0))) | E35: =IF($B35="","",INDEX(L_Desc,MATCH(1,L_WIdx,0))&"") | F35: =IF($B35="","",INDEX(L_Type,MATCH(1,L_WIdx,0))&"") | G35: =IF($B35="","",INDEX(L_Act,MATCH(1,L_WIdx,0))&"") | H35: =IF($B35="","",INDEX(L_Arr,MATCH(1,L_WIdx,0))) | I35: =IF($B35="","",N(INDEX(L_Pics,MATCH(1,L_WIdx,0))))
B36: =IF(ISNUMBER(MATCH(2,L_WIdx,0)),2,"") | C36: =IF($B36="","",INDEX(L_Date,MATCH(2,L_WIdx,0))) | D36: =IF($B36="","",INDEX(L_Area,MATCH(2,L_WIdx,0))&" - "&INDEX(L_Site,MATCH(2,L_WIdx,0))) | E36: =IF($B36="","",INDEX(L_Desc,MATCH(2,L_WIdx,0))&"") | F36: =IF($B36="","",INDEX(L_Type,MATCH(2,L_WIdx,0))&"") | G36: =IF($B36="","",INDEX(L_Act,MATCH(2,L_WIdx,0))&"") | H36: =IF($B36="","",INDEX(L_Arr,MATCH(2,L_WIdx,0))) | I36: =IF($B36="","",N(INDEX(L_Pics,MATCH(2,L_WIdx,0))))
B37: =IF(ISNUMBER(MATCH(3,L_WIdx,0)),3,"") | C37: =IF($B37="","",INDEX(L_Date,MATCH(3,L_WIdx,0))) | D37: =IF($B37="","",INDEX(L_Area,MATCH(3,L_WIdx,0))&" - "&INDEX(L_Site,MATCH(3,L_WIdx,0))) | E37: =IF($B37="","",INDEX(L_Desc,MATCH(3,L_WIdx,0))&"") | F37: =IF($B37="","",INDEX(L_Type,MATCH(3,L_WIdx,0))&"") | G37: =IF($B37="","",INDEX(L_Act,MATCH(3,L_WIdx,0))&"") | H37: =IF($B37="","",INDEX(L_Arr,MATCH(3,L_WIdx,0))) | I37: =IF($B37="","",N(INDEX(L_Pics,MATCH(3,L_WIdx,0))))
B38: =IF(ISNUMBER(MATCH(4,L_WIdx,0)),4,"") | C38: =IF($B38="","",INDEX(L_Date,MATCH(4,L_WIdx,0))) | D38: =IF($B38="","",INDEX(L_Area,MATCH(4,L_WIdx,0))&" - "&INDEX(L_Site,MATCH(4,L_WIdx,0))) | E38: =IF($B38="","",INDEX(L_Desc,MATCH(4,L_WIdx,0))&"") | F38: =IF($B38="","",INDEX(L_Type,MATCH(4,L_WIdx,0))&"") | G38: =IF($B38="","",INDEX(L_Act,MATCH(4,L_WIdx,0))&"") | H38: =IF($B38="","",INDEX(L_Arr,MATCH(4,L_WIdx,0))) | I38: =IF($B38="","",N(INDEX(L_Pics,MATCH(4,L_WIdx,0))))
B39: =IF(ISNUMBER(MATCH(5,L_WIdx,0)),5,"") | C39: =IF($B39="","",INDEX(L_Date,MATCH(5,L_WIdx,0))) | D39: =IF($B39="","",INDEX(L_Area,MATCH(5,L_WIdx,0))&" - "&INDEX(L_Site,MATCH(5,L_WIdx,0))) | E39: =IF($B39="","",INDEX(L_Desc,MATCH(5,L_WIdx,0))&"") | F39: =IF($B39="","",INDEX(L_Type,MATCH(5,L_WIdx,0))&"") | G39: =IF($B39="","",INDEX(L_Act,MATCH(5,L_WIdx,0))&"") | H39: =IF($B39="","",INDEX(L_Arr,MATCH(5,L_WIdx,0))) | I39: =IF($B39="","",N(INDEX(L_Pics,MATCH(5,L_WIdx,0))))
B40: =IF(ISNUMBER(MATCH(6,L_WIdx,0)),6,"") | C40: =IF($B40="","",INDEX(L_Date,MATCH(6,L_WIdx,0))) | D40: =IF($B40="","",INDEX(L_Area,MATCH(6,L_WIdx,0))&" - "&INDEX(L_Site,MATCH(6,L_WIdx,0))) | E40: =IF($B40="","",INDEX(L_Desc,MATCH(6,L_WIdx,0))&"") | F40: =IF($B40="","",INDEX(L_Type,MATCH(6,L_WIdx,0))&"") | G40: =IF($B40="","",INDEX(L_Act,MATCH(6,L_WIdx,0))&"") | H40: =IF($B40="","",INDEX(L_Arr,MATCH(6,L_WIdx,0))) | I40: =IF($B40="","",N(INDEX(L_Pics,MATCH(6,L_WIdx,0))))
B41: =IF(ISNUMBER(MATCH(7,L_WIdx,0)),7,"") | C41: =IF($B41="","",INDEX(L_Date,MATCH(7,L_WIdx,0))) | D41: =IF($B41="","",INDEX(L_Area,MATCH(7,L_WIdx,0))&" - "&INDEX(L_Site,MATCH(7,L_WIdx,0))) | E41: =IF($B41="","",INDEX(L_Desc,MATCH(7,L_WIdx,0))&"") | F41: =IF($B41="","",INDEX(L_Type,MATCH(7,L_WIdx,0))&"") | G41: =IF($B41="","",INDEX(L_Act,MATCH(7,L_WIdx,0))&"") | H41: =IF($B41="","",INDEX(L_Arr,MATCH(7,L_WIdx,0))) | I41: =IF($B41="","",N(INDEX(L_Pics,MATCH(7,L_WIdx,0))))
B42: =IF(ISNUMBER(MATCH(8,L_WIdx,0)),8,"") | C42: =IF($B42="","",INDEX(L_Date,MATCH(8,L_WIdx,0))) | D42: =IF($B42="","",INDEX(L_Area,MATCH(8,L_WIdx,0))&" - "&INDEX(L_Site,MATCH(8,L_WIdx,0))) | E42: =IF($B42="","",INDEX(L_Desc,MATCH(8,L_WIdx,0))&"") | F42: =IF($B42="","",INDEX(L_Type,MATCH(8,L_WIdx,0))&"") | G42: =IF($B42="","",INDEX(L_Act,MATCH(8,L_WIdx,0))&"") | H42: =IF($B42="","",INDEX(L_Arr,MATCH(8,L_WIdx,0))) | I42: =IF($B42="","",N(INDEX(L_Pics,MATCH(8,L_WIdx,0))))
B43: =IF(ISNUMBER(MATCH(9,L_WIdx,0)),9,"") | C43: =IF($B43="","",INDEX(L_Date,MATCH(9,L_WIdx,0))) | D43: =IF($B43="","",INDEX(L_Area,MATCH(9,L_WIdx,0))&" - "&INDEX(L_Site,MATCH(9,L_WIdx,0))) | E43: =IF($B43="","",INDEX(L_Desc,MATCH(9,L_WIdx,0))&"") | F43: =IF($B43="","",INDEX(L_Type,MATCH(9,L_WIdx,0))&"") | G43: =IF($B43="","",INDEX(L_Act,MATCH(9,L_WIdx,0))&"") | H43: =IF($B43="","",INDEX(L_Arr,MATCH(9,L_WIdx,0))) | I43: =IF($B43="","",N(INDEX(L_Pics,MATCH(9,L_WIdx,0))))
B44: =IF(ISNUMBER(MATCH(10,L_WIdx,0)),10,"") | C44: =IF($B44="","",INDEX(L_Date,MATCH(10,L_WIdx,0))) | D44: =IF($B44="","",INDEX(L_Area,MATCH(10,L_WIdx,0))&" - "&INDEX(L_Site,MATCH(10,L_WIdx,0))) | E44: =IF($B44="","",INDEX(L_Desc,MATCH(10,L_WIdx,0))&"") | F44: =IF($B44="","",INDEX(L_Type,MATCH(10,L_WIdx,0))&"") | G44: =IF($B44="","",INDEX(L_Act,MATCH(10,L_WIdx,0))&"") | H44: =IF($B44="","",INDEX(L_Arr,MATCH(10,L_WIdx,0))) | I44: =IF($B44="","",N(INDEX(L_Pics,MATCH(10,L_WIdx,0))))
B45: =IF(ISNUMBER(MATCH(11,L_WIdx,0)),11,"") | C45: =IF($B45="","",INDEX(L_Date,MATCH(11,L_WIdx,0))) | D45: =IF($B45="","",INDEX(L_Area,MATCH(11,L_WIdx,0))&" - "&INDEX(L_Site,MATCH(11,L_WIdx,0))) | E45: =IF($B45="","",INDEX(L_Desc,MATCH(11,L_WIdx,0))&"") | F45: =IF($B45="","",INDEX(L_Type,MATCH(11,L_WIdx,0))&"") | G45: =IF($B45="","",INDEX(L_Act,MATCH(11,L_WIdx,0))&"") | H45: =IF($B45="","",INDEX(L_Arr,MATCH(11,L_WIdx,0))) | I45: =IF($B45="","",N(INDEX(L_Pics,MATCH(11,L_WIdx,0))))
...

Sheet التقرير الشهري
B1: التقرير الشهري للتفتيش البيئي
B2: =OrgName&" | "&SectorName
B4: السنة: | D4: 2026 | E4: الشهر: | F4: أكتوبر | H4: =MATCH(F4,MonthList,0) | I4: =DATE(D4,H4,1)
B5: الفترة: | D5: ="من "&TEXT(I4,"yyyy/mm/dd")&" إلى "&TEXT(EOMONTH(I4,0),"yyyy/mm/dd")
B6: المفتش: | D6: =InspectorName
B8: الزيارات | D8: المشاهدات البيئية | E8: المخالفات المحررة | F8: مشاهدات دون مخالف | H8: زيارات بلا مشاهدات
B9: =SUMIFS(L_NewVisit,L_Year,$D$4,L_Month,$H$4) | D9: =SUMIFS(L_Obs,L_Year,$D$4,L_Month,$H$4) | E9: =SUMIFS(L_Viol,L_Year,$D$4,L_Month,$H$4) | F9: =COUNTIFS(L_Year,$D$4,L_Month,$H$4,L_Act,"مشاهدة فقط") | H9: =COUNTIFS(L_Year,$D$4,L_Month,$H$4,L_Type,"لا توجد مشاهدات")
B11: حسب المنطقة
B12: المنطقة | D12: الزيارات | E12: المشاهدات البيئية | F12: مخالفات محررة | G12: دون مخالف | H12: بلا مشاهدات | I12: النسبة
B13: =IF(INDEX(AreaHdr,1)="","",INDEX(AreaHdr,1)) | D13: =IF($B13="","",SUMIFS(L_NewVisit,L_Year,$D$4,L_Month,$H$4,L_Area,$B13)) | E13: =IF($B13="","",SUMIFS(L_Obs,L_Year,$D$4,L_Month,$H$4,L_Area,$B13)) | F13: =IF($B13="","",SUMIFS(L_Viol,L_Year,$D$4,L_Month,$H$4,L_Area,$B13)) | G13: =IF($B13="","",COUNTIFS(L_Year,$D$4,L_Month,$H$4,L_Area,$B13,L_Act,"مشاهدة فقط")) | H13: =IF($B13="","",COUNTIFS(L_Year,$D$4,L_Month,$H$4,L_Area,$B13,L_Type,"لا توجد مشاهدات")) | I13: =IF(OR($B13="",SUM($D$13:$D$22)=0),"",D13/SUM($D$13:$D$22))
B14: =IF(INDEX(AreaHdr,2)="","",INDEX(AreaHdr,2)) | D14: =IF($B14="","",SUMIFS(L_NewVisit,L_Year,$D$4,L_Month,$H$4,L_Area,$B14)) | E14: =IF($B14="","",SUMIFS(L_Obs,L_Year,$D$4,L_Month,$H$4,L_Area,$B14)) | F14: =IF($B14="","",SUMIFS(L_Viol,L_Year,$D$4,L_Month,$H$4,L_Area,$B14)) | G14: =IF($B14="","",COUNTIFS(L_Year,$D$4,L_Month,$H$4,L_Area,$B14,L_Act,"مشاهدة فقط")) | H14: =IF($B14="","",COUNTIFS(L_Year,$D$4,L_Month,$H$4,L_Area,$B14,L_Type,"لا توجد مشاهدات")) | I14: =IF(OR($B14="",SUM($D$13:$D$22)=0),"",D14/SUM($D$13:$D$22))
B15: =IF(INDEX(AreaHdr,3)="","",INDEX(AreaHdr,3)) | D15: =IF($B15="","",SUMIFS(L_NewVisit,L_Year,$D$4,L_Month,$H$4,L_Area,$B15)) | E15: =IF($B15="","",SUMIFS(L_Obs,L_Year,$D$4,L_Month,$H$4,L_Area,$B15)) | F15: =IF($B15="","",SUMIFS(L_Viol,L_Year,$D$4,L_Month,$H$4,L_Area,$B15)) | G15: =IF($B15="","",COUNTIFS(L_Year,$D$4,L_Month,$H$4,L_Area,$B15,L_Act,"مشاهدة فقط")) | H15: =IF($B15="","",COUNTIFS(L_Year,$D$4,L_Month,$H$4,L_Area,$B15,L_Type,"لا توجد مشاهدات")) | I15: =IF(OR($B15="",SUM($D$13:$D$22)=0),"",D15/SUM($D$13:$D$22))
B16: =IF(INDEX(AreaHdr,4)="","",INDEX(AreaHdr,4)) | D16: =IF($B16="","",SUMIFS(L_NewVisit,L_Year,$D$4,L_Month,$H$4,L_Area,$B16)) | E16: =IF($B16="","",SUMIFS(L_Obs,L_Year,$D$4,L_Month,$H$4,L_Area,$B16)) | F16: =IF($B16="","",SUMIFS(L_Viol,L_Year,$D$4,L_Month,$H$4,L_Area,$B16)) | G16: =IF($B16="","",COUNTIFS(L_Year,$D$4,L_Month,$H$4,L_Area,$B16,L_Act,"مشاهدة فقط")) | H16: =IF($B16="","",COUNTIFS(L_Year,$D$4,L_Month,$H$4,L_Area,$B16,L_Type,"لا توجد مشاهدات")) | I16: =IF(OR($B16="",SUM($D$13:$D$22)=0),"",D16/SUM($D$13:$D$22))
B17: =IF(INDEX(AreaHdr,5)="","",INDEX(AreaHdr,5)) | D17: =IF($B17="","",SUMIFS(L_NewVisit,L_Year,$D$4,L_Month,$H$4,L_Area,$B17)) | E17: =IF($B17="","",SUMIFS(L_Obs,L_Year,$D$4,L_Month,$H$4,L_Area,$B17)) | F17: =IF($B17="","",SUMIFS(L_Viol,L_Year,$D$4,L_Month,$H$4,L_Area,$B17)) | G17: =IF($B17="","",COUNTIFS(L_Year,$D$4,L_Month,$H$4,L_Area,$B17,L_Act,"مشاهدة فقط")) | H17: =IF($B17="","",COUNTIFS(L_Year,$D$4,L_Month,$H$4,L_Area,$B17,L_Type,"لا توجد مشاهدات")) | I17: =IF(OR($B17="",SUM($D$13:$D$22)=0),"",D17/SUM($D$13:$D$22))
B18: =IF(INDEX(AreaHdr,6)="","",INDEX(AreaHdr,6)) | D18: =IF($B18="","",SUMIFS(L_NewVisit,L_Year,$D$4,L_Month,$H$4,L_Area,$B18)) | E18: =IF($B18="","",SUMIFS(L_Obs,L_Year,$D$4,L_Month,$H$4,L_Area,$B18)) | F18: =IF($B18="","",SUMIFS(L_Viol,L_Year,$D$4,L_Month,$H$4,L_Area,$B18)) | G18: =IF($B18="","",COUNTIFS(L_Year,$D$4,L_Month,$H$4,L_Area,$B18,L_Act,"مشاهدة فقط")) | H18: =IF($B18="","",COUNTIFS(L_Year,$D$4,L_Month,$H$4,L_Area,$B18,L_Type,"لا توجد مشاهدات")) | I18: =IF(OR($B18="",SUM($D$13:$D$22)=0),"",D18/SUM($D$13:$D$22))
B19: =IF(INDEX(AreaHdr,7)="","",INDEX(AreaHdr,7)) | D19: =IF($B19="","",SUMIFS(L_NewVisit,L_Year,$D$4,L_Month,$H$4,L_Area,$B19)) | E19: =IF($B19="","",SUMIFS(L_Obs,L_Year,$D$4,L_Month,$H$4,L_Area,$B19)) | F19: =IF($B19="","",SUMIFS(L_Viol,L_Year,$D$4,L_Month,$H$4,L_Area,$B19)) | G19: =IF($B19="","",COUNTIFS(L_Year,$D$4,L_Month,$H$4,L_Area,$B19,L_Act,"مشاهدة فقط")) | H19: =IF($B19="","",COUNTIFS(L_Year,$D$4,L_Month,$H$4,L_Area,$B19,L_Type,"لا توجد مشاهدات")) | I19: =IF(OR($B19="",SUM($D$13:$D$22)=0),"",D19/SUM($D$13:$D$22))
B20: =IF(INDEX(AreaHdr,8)="","",INDEX(AreaHdr,8)) | D20: =IF($B20="","",SUMIFS(L_NewVisit,L_Year,$D$4,L_Month,$H$4,L_Area,$B20)) | E20: =IF($B20="","",SUMIFS(L_Obs,L_Year,$D$4,L_Month,$H$4,L_Area,$B20)) | F20: =IF($B20="","",SUMIFS(L_Viol,L_Year,$D$4,L_Month,$H$4,L_Area,$B20)) | G20: =IF($B20="","",COUNTIFS(L_Year,$D$4,L_Month,$H$4,L_Area,$B20,L_Act,"مشاهدة فقط")) | H20: =IF($B20="","",COUNTIFS(L_Year,$D$4,L_Month,$H$4,L_Area,$B20,L_Type,"لا توجد مشاهدات")) | I20: =IF(OR($B20="",SUM($D$13:$D$22)=0),"",D20/SUM($D$13:$D$22))
B21: =IF(INDEX(AreaHdr,9)="","",INDEX(AreaHdr,9)) | D21: =IF($B21="","",SUMIFS(L_NewVisit,L_Year,$D$4,L_Month,$H$4,L_Area,$B21)) | E21: =IF($B21="","",SUMIFS(L_Obs,L_Year,$D$4,L_Month,$H$4,L_Area,$B21)) | F21: =IF($B21="","",SUMIFS(L_Viol,L_Year,$D$4,L_Month,$H$4,L_Area,$B21)) | G21: =IF($B21="","",COUNTIFS(L_Year,$D$4,L_Month,$H$4,L_Area,$B21,L_Act,"مشاهدة فقط")) | H21: =IF($B21="","",COUNTIFS(L_Year,$D$4,L_Month,$H$4,L_Area,$B21,L_Type,"لا توجد مشاهدات")) | I21: =IF(OR($B21="",SUM($D$13:$D$22)=0),"",D21/SUM($D$13:$D$22))
B22: =IF(INDEX(AreaHdr,10)="","",INDEX(AreaHdr,10)) | D22: =IF($B22="","",SUMIFS(L_NewVisit,L_Year,$D$4,L_Month,$H$4,L_Area,$B22)) | E22: =IF($B22="","",SUMIFS(L_Obs,L_Year,$D$4,L_Month,$H$4,L_Area,$B22)) | F22: =IF($B22="","",SUMIFS(L_Viol,L_Year,$D$4,L_Month,$H$4,L_Area,$B22)) | G22: =IF($B22="","",COUNTIFS(L_Year,$D$4,L_Month,$H$4,L_Area,$B22,L_Act,"مشاهدة فقط")) | H22: =IF($B22="","",COUNTIFS(L_Year,$D$4,L_Month,$H$4,L_Area,$B22,L_Type,"لا توجد مشاهدات")) | I22: =IF(OR($B22="",SUM($D$13:$D$22)=0),"",D22/SUM($D$13:$D$22))
B23: الإجمالي | D23: =SUM(D13:D22) | E23: =SUM(E13:E22) | F23: =SUM(F13:F22) | G23: =SUM(G13:G22) | H23: =SUM(H13:H22)
B25: حسب الأسبوع
B26: الأسبوع | E26: الفترة | F26: الزيارات | G26: المشاهدات | H26: المخالفات | I26: دون مخالف
B27: =IF(($I$4-WEEKDAY($I$4,3)+0)>EOMONTH($I$4,0),"","الأسبوع "&1) | E27: =IF($B27="","",TEXT(MAX(($I$4-WEEKDAY($I$4,3)+0),$I$4),"mm/dd")&" - "&TEXT(MIN(($I$4-WEEKDAY($I$4,3)+0)+6,EOMONTH($I$4,0)),"mm/dd")) | F27: =IF($B27="","",SUMIFS(L_NewVisit,L_Week,($I$4-WEEKDAY($I$4,3)+0),L_Year,$D$4,L_Month,$H$4)) | G27: =IF($B27="","",SUMIFS(L_Obs,L_Week,($I$4-WEEKDAY($I$4,3)+0),L_Year,$D$4,L_Month,$H$4)) | H27: =IF($B27="","",SUMIFS(L_Viol,L_Week,($I$4-WEEKDAY($I$4,3)+0),L_Year,$D$4,L_Month,$H$4)) | I27: =IF($B27="","",COUNTIFS(L_Week,($I$4-WEEKDAY($I$4,3)+0),L_Year,$D$4,L_Month,$H$4,L_Act,"مشاهدة فقط"))
B28: =IF(($I$4-WEEKDAY($I$4,3)+7)>EOMONTH($I$4,0),"","الأسبوع "&2) | E28: =IF($B28="","",TEXT(MAX(($I$4-WEEKDAY($I$4,3)+7),$I$4),"mm/dd")&" - "&TEXT(MIN(($I$4-WEEKDAY($I$4,3)+7)+6,EOMONTH($I$4,0)),"mm/dd")) | F28: =IF($B28="","",SUMIFS(L_NewVisit,L_Week,($I$4-WEEKDAY($I$4,3)+7),L_Year,$D$4,L_Month,$H$4)) | G28: =IF($B28="","",SUMIFS(L_Obs,L_Week,($I$4-WEEKDAY($I$4,3)+7),L_Year,$D$4,L_Month,$H$4)) | H28: =IF($B28="","",SUMIFS(L_Viol,L_Week,($I$4-WEEKDAY($I$4,3)+7),L_Year,$D$4,L_Month,$H$4)) | I28: =IF($B28="","",COUNTIFS(L_Week,($I$4-WEEKDAY($I$4,3)+7),L_Year,$D$4,L_Month,$H$4,L_Act,"مشاهدة فقط"))
B29: =IF(($I$4-WEEKDAY($I$4,3)+14)>EOMONTH($I$4,0),"","الأسبوع "&3) | E29: =IF($B29="","",TEXT(MAX(($I$4-WEEKDAY($I$4,3)+14),$I$4),"mm/dd")&" - "&TEXT(MIN(($I$4-WEEKDAY($I$4,3)+14)+6,EOMONTH($I$4,0)),"mm/dd")) | F29: =IF($B29="","",SUMIFS(L_NewVisit,L_Week,($I$4-WEEKDAY($I$4,3)+14),L_Year,$D$4,L_Month,$H$4)) | G29: =IF($B29="","",SUMIFS(L_Obs,L_Week,($I$4-WEEKDAY($I$4,3)+14),L_Year,$D$4,L_Month,$H$4)) | H29: =IF($B29="","",SUMIFS(L_Viol,L_Week,($I$4-WEEKDAY($I$4,3)+14),L_Year,$D$4,L_Month,$H$4)) | I29: =IF($B29="","",COUNTIFS(L_Week,($I$4-WEEKDAY($I$4,3)+14),L_Year,$D$4,L_Month,$H$4,L_Act,"مشاهدة فقط"))
B30: =IF(($I$4-WEEKDAY($I$4,3)+21)>EOMONTH($I$4,0),"","الأسبوع "&4) | E30: =IF($B30="","",TEXT(MAX(($I$4-WEEKDAY($I$4,3)+21),$I$4),"mm/dd")&" - "&TEXT(MIN(($I$4-WEEKDAY($I$4,3)+21)+6,EOMONTH($I$4,0)),"mm/dd")) | F30: =IF($B30="","",SUMIFS(L_NewVisit,L_Week,($I$4-WEEKDAY($I$4,3)+21),L_Year,$D$4,L_Month,$H$4)) | G30: =IF($B30="","",SUMIFS(L_Obs,L_Week,($I$4-WEEKDAY($I$4,3)+21),L_Year,$D$4,L_Month,$H$4)) | H30: =IF($B30="","",SUMIFS(L_Viol,L_Week,($I$4-WEEKDAY($I$4,3)+21),L_Year,$D$4,L_Month,$H$4)) | I30: =IF($B30="","",COUNTIFS(L_Week,($I$4-WEEKDAY($I$4,3)+21),L_Year,$D$4,L_Month,$H$4,L_Act,"مشاهدة فقط"))
B31: =IF(($I$4-WEEKDAY($I$4,3)+28)>EOMONTH($I$4,0),"","الأسبوع "&5) | E31: =IF($B31="","",TEXT(MAX(($I$4-WEEKDAY($I$4,3)+28),$I$4),"mm/dd")&" - "&TEXT(MIN(($I$4-WEEKDAY($I$4,3)+28)+6,EOMONTH($I$4,0)),"mm/dd")) | F31: =IF($B31="","",SUMIFS(L_NewVisit,L_Week,($I$4-WEEKDAY($I$4,3)+28),L_Year,$D$4,L_Month,$H$4)) | G31: =IF($B31="","",SUMIFS(L_Obs,L_Week,($I$4-WEEKDAY($I$4,3)+28),L_Year,$D$4,L_Month,$H$4)) | H31: =IF($B31="","",SUMIFS(L_Viol,L_Week,($I$4-WEEKDAY($I$4,3)+28),L_Year,$D$4,L_Month,$H$4)) | I31: =IF($B31="","",COUNTIFS(L_Week,($I$4-WEEKDAY($I$4,3)+28),L_Year,$D$4,L_Month,$H$4,L_Act,"مشاهدة فقط"))
B32: =IF(($I$4-WEEKDAY($I$4,3)+35)>EOMONTH($I$4,0),"","الأسبوع "&6) | E32: =IF($B32="","",TEXT(MAX(($I$4-WEEKDAY($I$4,3)+35),$I$4),"mm/dd")&" - "&TEXT(MIN(($I$4-WEEKDAY($I$4,3)+35)+6,EOMONTH($I$4,0)),"mm/dd")) | F32: =IF($B32="","",SUMIFS(L_NewVisit,L_Week,($I$4-WEEKDAY($I$4,3)+35),L_Year,$D$4,L_Month,$H$4)) | G32: =IF($B32="","",SUMIFS(L_Obs,L_Week,($I$4-WEEKDAY($I$4,3)+35),L_Year,$D$4,L_Month,$H$4)) | H32: =IF($B32="","",SUMIFS(L_Viol,L_Week,($I$4-WEEKDAY($I$4,3)+35),L_Year,$D$4,L_Month,$H$4)) | I32: =IF($B32="","",COUNTIFS(L_Week,($I$4-WEEKDAY($I$4,3)+35),L_Year,$D$4,L_Month,$H$4,L_Act,"مشاهدة فقط"))
B34: حسب نوع المشاهدة
B35: نوع المشاهدة | F35: العدد | G35: مخالفة محررة | H35: دون مخالف | I35: النسبة
B36: =IF(INDEX('الإعدادات'!$L$12:$L$26,1)="","",INDEX('الإعدادات'!$L$12:$L$26,1)) | F36: =IF($B36="","",COUNTIFS(L_Year,$D$4,L_Month,$H$4,L_Type,$B36)) | G36: =IF($B36="","",COUNTIFS(L_Year,$D$4,L_Month,$H$4,L_Type,$B36,L_Act,"تم تحرير مخالفة")) | H36: =IF($B36="","",COUNTIFS(L_Year,$D$4,L_Month,$H$4,L_Type,$B36,L_Act,"مشاهدة فقط")) | I36: =IF(OR($B36="",SUM($F$36:$F$45)=0),"",F36/SUM($F$36:$F$45))
B37: =IF(INDEX('الإعدادات'!$L$12:$L$26,2)="","",INDEX('الإعدادات'!$L$12:$L$26,2)) | F37: =IF($B37="","",COUNTIFS(L_Year,$D$4,L_Month,$H$4,L_Type,$B37)) | G37: =IF($B37="","",COUNTIFS(L_Year,$D$4,L_Month,$H$4,L_Type,$B37,L_Act,"تم تحرير مخالفة")) | H37: =IF($B37="","",COUNTIFS(L_Year,$D$4,L_Month,$H$4,L_Type,$B37,L_Act,"مشاهدة فقط")) | I37: =IF(OR($B37="",SUM($F$36:$F$45)=0),"",F37/SUM($F$36:$F$45))
B38: =IF(INDEX('الإعدادات'!$L$12:$L$26,3)="","",INDEX('الإعدادات'!$L$12:$L$26,3)) | F38: =IF($B38="","",COUNTIFS(L_Year,$D$4,L_Month,$H$4,L_Type,$B38)) | G38: =IF($B38="","",COUNTIFS(L_Year,$D$4,L_Month,$H$4,L_Type,$B38,L_Act,"تم تحرير مخالفة")) | H38: =IF($B38="","",COUNTIFS(L_Year,$D$4,L_Month,$H$4,L_Type,$B38,L_Act,"مشاهدة فقط")) | I38: =IF(OR($B38="",SUM($F$36:$F$45)=0),"",F38/SUM($F$36:$F$45))
B39: =IF(INDEX('الإعدادات'!$L$12:$L$26,4)="","",INDEX('الإعدادات'!$L$12:$L$26,4)) | F39: =IF($B39="","",COUNTIFS(L_Year,$D$4,L_Month,$H$4,L_Type,$B39)) | G39: =IF($B39="","",COUNTIFS(L_Year,$D$4,L_Month,$H$4,L_Type,$B39,L_Act,"تم تحرير مخالفة")) | H39: =IF($B39="","",COUNTIFS(L_Year,$D$4,L_Month,$H$4,L_Type,$B39,L_Act,"مشاهدة فقط")) | I39: =IF(OR($B39="",SUM($F$36:$F$45)=0),"",F39/SUM($F$36:$F$45))
B40: =IF(INDEX('الإعدادات'!$L$12:$L$26,5)="","",INDEX('الإعدادات'!$L$12:$L$26,5)) | F40: =IF($B40="","",COUNTIFS(L_Year,$D$4,L_Month,$H$4,L_Type,$B40)) | G40: =IF($B40="","",COUNTIFS(L_Year,$D$4,L_Month,$H$4,L_Type,$B40,L_Act,"تم تحرير مخالفة")) | H40: =IF($B40="","",COUNTIFS(L_Year,$D$4,L_Month,$H$4,L_Type,$B40,L_Act,"مشاهدة فقط")) | I40: =IF(OR($B40="",SUM($F$36:$F$45)=0),"",F40/SUM($F$36:$F$45))
B41: =IF(INDEX('الإعدادات'!$L$12:$L$26,6)="","",INDEX('الإعدادات'!$L$12:$L$26,6)) | F41: =IF($B41="","",COUNTIFS(L_Year,$D$4,L_Month,$H$4,L_Type,$B41)) | G41: =IF($B41="","",COUNTIFS(L_Year,$D$4,L_Month,$H$4,L_Type,$B41,L_Act,"تم تحرير مخالفة")) | H41: =IF($B41="","",COUNTIFS(L_Year,$D$4,L_Month,$H$4,L_Type,$B41,L_Act,"مشاهدة فقط")) | I41: =IF(OR($B41="",SUM($F$36:$F$45)=0),"",F41/SUM($F$36:$F$45))
B42: =IF(INDEX('الإعدادات'!$L$12:$L$26,7)="","",INDEX('الإعدادات'!$L$12:$L$26,7)) | F42: =IF($B42="","",COUNTIFS(L_Year,$D$4,L_Month,$H$4,L_Type,$B42)) | G42: =IF($B42="","",COUNTIFS(L_Year,$D$4,L_Month,$H$4,L_Type,$B42,L_Act,"تم تحرير مخالفة")) | H42: =IF($B42="","",COUNTIFS(L_Year,$D$4,L_Month,$H$4,L_Type,$B42,L_Act,"مشاهدة فقط")) | I42: =IF(OR($B42="",SUM($F$36:$F$45)=0),"",F42/SUM($F$36:$F$45))
B43: =IF(INDEX('الإعدادات'!$L$12:$L$26,8)="","",INDEX('الإعدادات'!$L$12:$L$26,8)) | F43: =IF($B43="","",COUNTIFS(L_Year,$D$4,L_Month,$H$4,L_Type,$B43)) | G43: =IF($B43="","",COUNTIFS(L_Year,$D$4,L_Month,$H$4,L_Type,$B43,L_Act,"تم تحرير مخالفة")) | H43: =IF($B43="","",COUNTIFS(L_Year,$D$4,L_Month,$H$4,L_Type,$B43,L_Act,"مشاهدة فقط")) | I43: =IF(OR($B43="",SUM($F$36:$F$45)=0),"",F43/SUM($F$36:$F$45))
B44: =IF(INDEX('الإعدادات'!$L$12:$L$26,9)="","",INDEX('الإعدادات'!$L$12:$L$26,9)) | F44: =IF($B44="","",COUNTIFS(L_Year,$D$4,L_Month,$H$4,L_Type,$B44)) | G44: =IF($B44="","",COUNTIFS(L_Year,$D$4,L_Month,$H$4,L_Type,$B44,L_Act,"تم تحرير مخالفة")) | H44: =IF($B44="","",COUNTIFS(L_Year,$D$4,L_Month,$H$4,L_Type,$B44,L_Act,"مشاهدة فقط")) | I44: =IF(OR($B44="",SUM($F$36:$F$45)=0),"",F44/SUM($F$36:$F$45))
B45: =IF(INDEX('الإعدادات'!$L$12:$L$26,10)="","",INDEX('الإعدادات'!$L$12:$L$26,10)) | F45: =IF($B45="","",COUNTIFS(L_Year,$D$4,L_Month,$H$4,L_Type,$B45)) | G45: =IF($B45="","",COUNTIFS(L_Year,$D$4,L_Month,$H$4,L_Type,$B45,L_Act,"تم تحرير مخالفة")) | H45: =IF($B45="","",COUNTIFS(L_Year,$D$4,L_Month,$H$4,L_Type,$B45,L_Act,"مشاهدة فقط")) | I45: =IF(OR($B45="",SUM($F$36:$F$45)=0),"",F45/SUM($F$36:$F$45))
...

Sheet التقرير الدوري
B1: ="تقرير "&F4&" للتفتيش البيئي — "&D4
B2: =OrgName&" | "&SectorName
B4: السنة: | D4: 2026 | E4: الفترة: | F4: الربع الرابع | H4: =VLOOKUP(F4,PeriodTbl,2,FALSE) | I4: =VLOOKUP(F4,PeriodTbl,3,FALSE)
B5: الفترة: | D5: ="من "&TEXT(DATE(D4,H4,1),"yyyy/mm/dd")&" إلى "&TEXT(EOMONTH(DATE(D4,I4,1),0),"yyyy/mm/dd")
B6: المفتش: | D6: =InspectorName
B8: الزيارات | D8: المشاهدات البيئية | E8: المخالفات المحررة | F8: مشاهدات دون مخالف | H8: زيارات بلا مشاهدات
B9: =SUMIFS(L_NewVisit,L_Year,$D$4,L_Month,">="&$H$4,L_Month,"<="&$I$4) | D9: =SUMIFS(L_Obs,L_Year,$D$4,L_Month,">="&$H$4,L_Month,"<="&$I$4) | E9: =SUMIFS(L_Viol,L_Year,$D$4,L_Month,">="&$H$4,L_Month,"<="&$I$4) | F9: =COUNTIFS(L_Year,$D$4,L_Month,">="&$H$4,L_Month,"<="&$I$4,L_Act,"مشاهدة فقط") | H9: =COUNTIFS(L_Year,$D$4,L_Month,">="&$H$4,L_Month,"<="&$I$4,L_Type,"لا توجد مشاهدات")
B11: حسب الشهر
B12: الشهر | D12: الزيارات | E12: المشاهدات البيئية | F12: مخالفات محررة | G12: دون مخالف | H12: بلا مشاهدات | I12: الصور
B13: =IF(($H$4+0)>$I$4,"",INDEX(MonthList,($H$4+0))) | D13: =IF($B13="","",SUMIFS(L_NewVisit,L_Year,$D$4,L_Month,($H$4+0))) | E13: =IF($B13="","",SUMIFS(L_Obs,L_Year,$D$4,L_Month,($H$4+0))) | F13: =IF($B13="","",SUMIFS(L_Viol,L_Year,$D$4,L_Month,($H$4+0))) | G13: =IF($B13="","",COUNTIFS(L_Year,$D$4,L_Month,($H$4+0),L_Act,"مشاهدة فقط")) | H13: =IF($B13="","",COUNTIFS(L_Year,$D$4,L_Month,($H$4+0),L_Type,"لا توجد مشاهدات")) | I13: =IF($B13="","",SUMIFS(L_Pics,L_Year,$D$4,L_Month,($H$4+0)))
B14: =IF(($H$4+1)>$I$4,"",INDEX(MonthList,($H$4+1))) | D14: =IF($B14="","",SUMIFS(L_NewVisit,L_Year,$D$4,L_Month,($H$4+1))) | E14: =IF($B14="","",SUMIFS(L_Obs,L_Year,$D$4,L_Month,($H$4+1))) | F14: =IF($B14="","",SUMIFS(L_Viol,L_Year,$D$4,L_Month,($H$4+1))) | G14: =IF($B14="","",COUNTIFS(L_Year,$D$4,L_Month,($H$4+1),L_Act,"مشاهدة فقط")) | H14: =IF($B14="","",COUNTIFS(L_Year,$D$4,L_Month,($H$4+1),L_Type,"لا توجد مشاهدات")) | I14: =IF($B14="","",SUMIFS(L_Pics,L_Year,$D$4,L_Month,($H$4+1)))
B15: =IF(($H$4+2)>$I$4,"",INDEX(MonthList,($H$4+2))) | D15: =IF($B15="","",SUMIFS(L_NewVisit,L_Year,$D$4,L_Month,($H$4+2))) | E15: =IF($B15="","",SUMIFS(L_Obs,L_Year,$D$4,L_Month,($H$4+2))) | F15: =IF($B15="","",SUMIFS(L_Viol,L_Year,$D$4,L_Month,($H$4+2))) | G15: =IF($B15="","",COUNTIFS(L_Year,$D$4,L_Month,($H$4+2),L_Act,"مشاهدة فقط")) | H15: =IF($B15="","",COUNTIFS(L_Year,$D$4,L_Month,($H$4+2),L_Type,"لا توجد مشاهدات")) | I15: =IF($B15="","",SUMIFS(L_Pics,L_Year,$D$4,L_Month,($H$4+2)))
B16: =IF(($H$4+3)>$I$4,"",INDEX(MonthList,($H$4+3))) | D16: =IF($B16="","",SUMIFS(L_NewVisit,L_Year,$D$4,L_Month,($H$4+3))) | E16: =IF($B16="","",SUMIFS(L_Obs,L_Year,$D$4,L_Month,($H$4+3))) | F16: =IF($B16="","",SUMIFS(L_Viol,L_Year,$D$4,L_Month,($H$4+3))) | G16: =IF($B16="","",COUNTIFS(L_Year,$D$4,L_Month,($H$4+3),L_Act,"مشاهدة فقط")) | H16: =IF($B16="","",COUNTIFS(L_Year,$D$4,L_Month,($H$4+3),L_Type,"لا توجد مشاهدات")) | I16: =IF($B16="","",SUMIFS(L_Pics,L_Year,$D$4,L_Month,($H$4+3)))
B17: =IF(($H$4+4)>$I$4,"",INDEX(MonthList,($H$4+4))) | D17: =IF($B17="","",SUMIFS(L_NewVisit,L_Year,$D$4,L_Month,($H$4+4))) | E17: =IF($B17="","",SUMIFS(L_Obs,L_Year,$D$4,L_Month,($H$4+4))) | F17: =IF($B17="","",SUMIFS(L_Viol,L_Year,$D$4,L_Month,($H$4+4))) | G17: =IF($B17="","",COUNTIFS(L_Year,$D$4,L_Month,($H$4+4),L_Act,"مشاهدة فقط")) | H17: =IF($B17="","",COUNTIFS(L_Year,$D$4,L_Month,($H$4+4),L_Type,"لا توجد مشاهدات")) | I17: =IF($B17="","",SUMIFS(L_Pics,L_Year,$D$4,L_Month,($H$4+4)))
B18: =IF(($H$4+5)>$I$4,"",INDEX(MonthList,($H$4+5))) | D18: =IF($B18="","",SUMIFS(L_NewVisit,L_Year,$D$4,L_Month,($H$4+5))) | E18: =IF($B18="","",SUMIFS(L_Obs,L_Year,$D$4,L_Month,($H$4+5))) | F18: =IF($B18="","",SUMIFS(L_Viol,L_Year,$D$4,L_Month,($H$4+5))) | G18: =IF($B18="","",COUNTIFS(L_Year,$D$4,L_Month,($H$4+5),L_Act,"مشاهدة فقط")) | H18: =IF($B18="","",COUNTIFS(L_Year,$D$4,L_Month,($H$4+5),L_Type,"لا توجد مشاهدات")) | I18: =IF($B18="","",SUMIFS(L_Pics,L_Year,$D$4,L_Month,($H$4+5)))
B19: =IF(($H$4+6)>$I$4,"",INDEX(MonthList,($H$4+6))) | D19: =IF($B19="","",SUMIFS(L_NewVisit,L_Year,$D$4,L_Month,($H$4+6))) | E19: =IF($B19="","",SUMIFS(L_Obs,L_Year,$D$4,L_Month,($H$4+6))) | F19: =IF($B19="","",SUMIFS(L_Viol,L_Year,$D$4,L_Month,($H$4+6))) | G19: =IF($B19="","",COUNTIFS(L_Year,$D$4,L_Month,($H$4+6),L_Act,"مشاهدة فقط")) | H19: =IF($B19="","",COUNTIFS(L_Year,$D$4,L_Month,($H$4+6),L_Type,"لا توجد مشاهدات")) | I19: =IF($B19="","",SUMIFS(L_Pics,L_Year,$D$4,L_Month,($H$4+6)))
B20: =IF(($H$4+7)>$I$4,"",INDEX(MonthList,($H$4+7))) | D20: =IF($B20="","",SUMIFS(L_NewVisit,L_Year,$D$4,L_Month,($H$4+7))) | E20: =IF($B20="","",SUMIFS(L_Obs,L_Year,$D$4,L_Month,($H$4+7))) | F20: =IF($B20="","",SUMIFS(L_Viol,L_Year,$D$4,L_Month,($H$4+7))) | G20: =IF($B20="","",COUNTIFS(L_Year,$D$4,L_Month,($H$4+7),L_Act,"مشاهدة فقط")) | H20: =IF($B20="","",COUNTIFS(L_Year,$D$4,L_Month,($H$4+7),L_Type,"لا توجد مشاهدات")) | I20: =IF($B20="","",SUMIFS(L_Pics,L_Year,$D$4,L_Month,($H$4+7)))
B21: =IF(($H$4+8)>$I$4,"",INDEX(MonthList,($H$4+8))) | D21: =IF($B21="","",SUMIFS(L_NewVisit,L_Year,$D$4,L_Month,($H$4+8))) | E21: =IF($B21="","",SUMIFS(L_Obs,L_Year,$D$4,L_Month,($H$4+8))) | F21: =IF($B21="","",SUMIFS(L_Viol,L_Year,$D$4,L_Month,($H$4+8))) | G21: =IF($B21="","",COUNTIFS(L_Year,$D$4,L_Month,($H$4+8),L_Act,"مشاهدة فقط")) | H21: =IF($B21="","",COUNTIFS(L_Year,$D$4,L_Month,($H$4+8),L_Type,"لا توجد مشاهدات")) | I21: =IF($B21="","",SUMIFS(L_Pics,L_Year,$D$4,L_Month,($H$4+8)))
B22: =IF(($H$4+9)>$I$4,"",INDEX(MonthList,($H$4+9))) | D22: =IF($B22="","",SUMIFS(L_NewVisit,L_Year,$D$4,L_Month,($H$4+9))) | E22: =IF($B22="","",SUMIFS(L_Obs,L_Year,$D$4,L_Month,($H$4+9))) | F22: =IF($B22="","",SUMIFS(L_Viol,L_Year,$D$4,L_Month,($H$4+9))) | G22: =IF($B22="","",COUNTIFS(L_Year,$D$4,L_Month,($H$4+9),L_Act,"مشاهدة فقط")) | H22: =IF($B22="","",COUNTIFS(L_Year,$D$4,L_Month,($H$4+9),L_Type,"لا توجد مشاهدات")) | I22: =IF($B22="","",SUMIFS(L_Pics,L_Year,$D$4,L_Month,($H$4+9)))
B23: =IF(($H$4+10)>$I$4,"",INDEX(MonthList,($H$4+10))) | D23: =IF($B23="","",SUMIFS(L_NewVisit,L_Year,$D$4,L_Month,($H$4+10))) | E23: =IF($B23="","",SUMIFS(L_Obs,L_Year,$D$4,L_Month,($H$4+10))) | F23: =IF($B23="","",SUMIFS(L_Viol,L_Year,$D$4,L_Month,($H$4+10))) | G23: =IF($B23="","",COUNTIFS(L_Year,$D$4,L_Month,($H$4+10),L_Act,"مشاهدة فقط")) | H23: =IF($B23="","",COUNTIFS(L_Year,$D$4,L_Month,($H$4+10),L_Type,"لا توجد مشاهدات")) | I23: =IF($B23="","",SUMIFS(L_Pics,L_Year,$D$4,L_Month,($H$4+10)))
B24: =IF(($H$4+11)>$I$4,"",INDEX(MonthList,($H$4+11))) | D24: =IF($B24="","",SUMIFS(L_NewVisit,L_Year,$D$4,L_Month,($H$4+11))) | E24: =IF($B24="","",SUMIFS(L_Obs,L_Year,$D$4,L_Month,($H$4+11))) | F24: =IF($B24="","",SUMIFS(L_Viol,L_Year,$D$4,L_Month,($H$4+11))) | G24: =IF($B24="","",COUNTIFS(L_Year,$D$4,L_Month,($H$4+11),L_Act,"مشاهدة فقط")) | H24: =IF($B24="","",COUNTIFS(L_Year,$D$4,L_Month,($H$4+11),L_Type,"لا توجد مشاهدات")) | I24: =IF($B24="","",SUMIFS(L_Pics,L_Year,$D$4,L_Month,($H$4+11)))
B25: الإجمالي | D25: =SUM(D13:D24) | E25: =SUM(E13:E24) | F25: =SUM(F13:F24) | G25: =SUM(G13:G24) | H25: =SUM(H13:H24) | I25: =SUM(I13:I24)
B43: حسب المنطقة
B44: المنطقة | D44: الزيارات | E44: المشاهدات البيئية | F44: مخالفات محررة | G44: دون مخالف | H44: بلا مشاهدات | I44: النسبة
B45: =IF(INDEX(AreaHdr,1)="","",INDEX(AreaHdr,1)) | D45: =IF($B45="","",SUMIFS(L_NewVisit,L_Year,$D$4,L_Month,">="&$H$4,L_Month,"<="&$I$4,L_Area,$B45)) | E45: =IF($B45="","",SUMIFS(L_Obs,L_Year,$D$4,L_Month,">="&$H$4,L_Month,"<="&$I$4,L_Area,$B45)) | F45: =IF($B45="","",SUMIFS(L_Viol,L_Year,$D$4,L_Month,">="&$H$4,L_Month,"<="&$I$4,L_Area,$B45)) | G45: =IF($B45="","",COUNTIFS(L_Year,$D$4,L_Month,">="&$H$4,L_Month,"<="&$I$4,L_Area,$B45,L_Act,"مشاهدة فقط")) | H45: =IF($B45="","",COUNTIFS(L_Year,$D$4,L_Month,">="&$H$4,L_Month,"<="&$I$4,L_Area,$B45,L_Type,"لا توجد مشاهدات")) | I45: =IF(OR($B45="",SUM($D$45:$D$54)=0),"",D45/SUM($D$45:$D$54))
B46: =IF(INDEX(AreaHdr,2)="","",INDEX(AreaHdr,2)) | D46: =IF($B46="","",SUMIFS(L_NewVisit,L_Year,$D$4,L_Month,">="&$H$4,L_Month,"<="&$I$4,L_Area,$B46)) | E46: =IF($B46="","",SUMIFS(L_Obs,L_Year,$D$4,L_Month,">="&$H$4,L_Month,"<="&$I$4,L_Area,$B46)) | F46: =IF($B46="","",SUMIFS(L_Viol,L_Year,$D$4,L_Month,">="&$H$4,L_Month,"<="&$I$4,L_Area,$B46)) | G46: =IF($B46="","",COUNTIFS(L_Year,$D$4,L_Month,">="&$H$4,L_Month,"<="&$I$4,L_Area,$B46,L_Act,"مشاهدة فقط")) | H46: =IF($B46="","",COUNTIFS(L_Year,$D$4,L_Month,">="&$H$4,L_Month,"<="&$I$4,L_Area,$B46,L_Type,"لا توجد مشاهدات")) | I46: =IF(OR($B46="",SUM($D$45:$D$54)=0),"",D46/SUM($D$45:$D$54))
B47: =IF(INDEX(AreaHdr,3)="","",INDEX(AreaHdr,3)) | D47: =IF($B47="","",SUMIFS(L_NewVisit,L_Year,$D$4,L_Month,">="&$H$4,L_Month,"<="&$I$4,L_Area,$B47)) | E47: =IF($B47="","",SUMIFS(L_Obs,L_Year,$D$4,L_Month,">="&$H$4,L_Month,"<="&$I$4,L_Area,$B47)) | F47: =IF($B47="","",SUMIFS(L_Viol,L_Year,$D$4,L_Month,">="&$H$4,L_Month,"<="&$I$4,L_Area,$B47)) | G47: =IF($B47="","",COUNTIFS(L_Year,$D$4,L_Month,">="&$H$4,L_Month,"<="&$I$4,L_Area,$B47,L_Act,"مشاهدة فقط")) | H47: =IF($B47="","",COUNTIFS(L_Year,$D$4,L_Month,">="&$H$4,L_Month,"<="&$I$4,L_Area,$B47,L_Type,"لا توجد مشاهدات")) | I47: =IF(OR($B47="",SUM($D$45:$D$54)=0),"",D47/SUM($D$45:$D$54))
B48: =IF(INDEX(AreaHdr,4)="","",INDEX(AreaHdr,4)) | D48: =IF($B48="","",SUMIFS(L_NewVisit,L_Year,$D$4,L_Month,">="&$H$4,L_Month,"<="&$I$4,L_Area,$B48)) | E48: =IF($B48="","",SUMIFS(L_Obs,L_Year,$D$4,L_Month,">="&$H$4,L_Month,"<="&$I$4,L_Area,$B48)) | F48: =IF($B48="","",SUMIFS(L_Viol,L_Year,$D$4,L_Month,">="&$H$4,L_Month,"<="&$I$4,L_Area,$B48)) | G48: =IF($B48="","",COUNTIFS(L_Year,$D$4,L_Month,">="&$H$4,L_Month,"<="&$I$4,L_Area,$B48,L_Act,"مشاهدة فقط")) | H48: =IF($B48="","",COUNTIFS(L_Year,$D$4,L_Month,">="&$H$4,L_Month,"<="&$I$4,L_Area,$B48,L_Type,"لا توجد مشاهدات")) | I48: =IF(OR($B48="",SUM($D$45:$D$54)=0),"",D48/SUM($D$45:$D$54))
B49: =IF(INDEX(AreaHdr,5)="","",INDEX(AreaHdr,5)) | D49: =IF($B49="","",SUMIFS(L_NewVisit,L_Year,$D$4,L_Month,">="&$H$4,L_Month,"<="&$I$4,L_Area,$B49)) | E49: =IF($B49="","",SUMIFS(L_Obs,L_Year,$D$4,L_Month,">="&$H$4,L_Month,"<="&$I$4,L_Area,$B49)) | F49: =IF($B49="","",SUMIFS(L_Viol,L_Year,$D$4,L_Month,">="&$H$4,L_Month,"<="&$I$4,L_Area,$B49)) | G49: =IF($B49="","",COUNTIFS(L_Year,$D$4,L_Month,">="&$H$4,L_Month,"<="&$I$4,L_Area,$B49,L_Act,"مشاهدة فقط")) | H49: =IF($B49="","",COUNTIFS(L_Year,$D$4,L_Month,">="&$H$4,L_Month,"<="&$I$4,L_Area,$B49,L_Type,"لا توجد مشاهدات")) | I49: =IF(OR($B49="",SUM($D$45:$D$54)=0),"",D49/SUM($D$45:$D$54))
B50: =IF(INDEX(AreaHdr,6)="","",INDEX(AreaHdr,6)) | D50: =IF($B50="","",SUMIFS(L_NewVisit,L_Year,$D$4,L_Month,">="&$H$4,L_Month,"<="&$I$4,L_Area,$B50)) | E50: =IF($B50="","",SUMIFS(L_Obs,L_Year,$D$4,L_Month,">="&$H$4,L_Month,"<="&$I$4,L_Area,$B50)) | F50: =IF($B50="","",SUMIFS(L_Viol,L_Year,$D$4,L_Month,">="&$H$4,L_Month,"<="&$I$4,L_Area,$B50)) | G50: =IF($B50="","",COUNTIFS(L_Year,$D$4,L_Month,">="&$H$4,L_Month,"<="&$I$4,L_Area,$B50,L_Act,"مشاهدة فقط")) | H50: =IF($B50="","",COUNTIFS(L_Year,$D$4,L_Month,">="&$H$4,L_Month,"<="&$I$4,L_Area,$B50,L_Type,"لا توجد مشاهدات")) | I50: =IF(OR($B50="",SUM($D$45:$D$54)=0),"",D50/SUM($D$45:$D$54))
B51: =IF(INDEX(AreaHdr,7)="","",INDEX(AreaHdr,7)) | D51: =IF($B51="","",SUMIFS(L_NewVisit,L_Year,$D$4,L_Month,">="&$H$4,L_Month,"<="&$I$4,L_Area,$B51)) | E51: =IF($B51="","",SUMIFS(L_Obs,L_Year,$D$4,L_Month,">="&$H$4,L_Month,"<="&$I$4,L_Area,$B51)) | F51: =IF($B51="","",SUMIFS(L_Viol,L_Year,$D$4,L_Month,">="&$H$4,L_Month,"<="&$I$4,L_Area,$B51)) | G51: =IF($B51="","",COUNTIFS(L_Year,$D$4,L_Month,">="&$H$4,L_Month,"<="&$I$4,L_Area,$B51,L_Act,"مشاهدة فقط")) | H51: =IF($B51="","",COUNTIFS(L_Year,$D$4,L_Month,">="&$H$4,L_Month,"<="&$I$4,L_Area,$B51,L_Type,"لا توجد مشاهدات")) | I51: =IF(OR($B51="",SUM($D$45:$D$54)=0),"",D51/SUM($D$45:$D$54))
B52: =IF(INDEX(AreaHdr,8)="","",INDEX(AreaHdr,8)) | D52: =IF($B52="","",SUMIFS(L_NewVisit,L_Year,$D$4,L_Month,">="&$H$4,L_Month,"<="&$I$4,L_Area,$B52)) | E52: =IF($B52="","",SUMIFS(L_Obs,L_Year,$D$4,L_Month,">="&$H$4,L_Month,"<="&$I$4,L_Area,$B52)) | F52: =IF($B52="","",SUMIFS(L_Viol,L_Year,$D$4,L_Month,">="&$H$4,L_Month,"<="&$I$4,L_Area,$B52)) | G52: =IF($B52="","",COUNTIFS(L_Year,$D$4,L_Month,">="&$H$4,L_Month,"<="&$I$4,L_Area,$B52,L_Act,"مشاهدة فقط")) | H52: =IF($B52="","",COUNTIFS(L_Year,$D$4,L_Month,">="&$H$4,L_Month,"<="&$I$4,L_Area,$B52,L_Type,"لا توجد مشاهدات")) | I52: =IF(OR($B52="",SUM($D$45:$D$54)=0),"",D52/SUM($D$45:$D$54))
B53: =IF(INDEX(AreaHdr,9)="","",INDEX(AreaHdr,9)) | D53: =IF($B53="","",SUMIFS(L_NewVisit,L_Year,$D$4,L_Month,">="&$H$4,L_Month,"<="&$I$4,L_Area,$B53)) | E53: =IF($B53="","",SUMIFS(L_Obs,L_Year,$D$4,L_Month,">="&$H$4,L_Month,"<="&$I$4,L_Area,$B53)) | F53: =IF($B53="","",SUMIFS(L_Viol,L_Year,$D$4,L_Month,">="&$H$4,L_Month,"<="&$I$4,L_Area,$B53)) | G53: =IF($B53="","",COUNTIFS(L_Year,$D$4,L_Month,">="&$H$4,L_Month,"<="&$I$4,L_Area,$B53,L_Act,"مشاهدة فقط")) | H53: =IF($B53="","",COUNTIFS(L_Year,$D$4,L_Month,">="&$H$4,L_Month,"<="&$I$4,L_Area,$B53,L_Type,"لا توجد مشاهدات")) | I53: =IF(OR($B53="",SUM($D$45:$D$54)=0),"",D53/SUM($D$45:$D$54))
B54: =IF(INDEX(AreaHdr,10)="","",INDEX(AreaHdr,10)) | D54: =IF($B54="","",SUMIFS(L_NewVisit,L_Year,$D$4,L_Month,">="&$H$4,L_Month,"<="&$I$4,L_Area,$B54)) | E54: =IF($B54="","",SUMIFS(L_Obs,L_Year,$D$4,L_Month,">="&$H$4,L_Month,"<="&$I$4,L_Area,$B54)) | F54: =IF($B54="","",SUMIFS(L_Viol,L_Year,$D$4,L_Month,">="&$H$4,L_Month,"<="&$I$4,L_Area,$B54)) | G54: =IF($B54="","",COUNTIFS(L_Year,$D$4,L_Month,">="&$H$4,L_Month,"<="&$I$4,L_Area,$B54,L_Act,"مشاهدة فقط")) | H54: =IF($B54="","",COUNTIFS(L_Year,$D$4,L_Month,">="&$H$4,L_Month,"<="&$I$4,L_Area,$B54,L_Type,"لا توجد مشاهدات")) | I54: =IF(OR($B54="",SUM($D$45:$D$54)=0),"",D54/SUM($D$45:$D$54))
B55: الإجمالي | D55: =SUM(D45:D54) | E55: =SUM(E45:E54) | F55: =SUM(F45:F54) | G55: =SUM(G45:G54) | H55: =SUM(H45:H54)
B57: حسب نوع المشاهدة
B58: نوع المشاهدة | F58: العدد | G58: مخالفة محررة | H58: دون مخالف | I58: النسبة
B59: =IF(INDEX('الإعدادات'!$L$12:$L$26,1)="","",INDEX('الإعدادات'!$L$12:$L$26,1)) | F59: =IF($B59="","",COUNTIFS(L_Year,$D$4,L_Month,">="&$H$4,L_Month,"<="&$I$4,L_Type,$B59)) | G59: =IF($B59="","",COUNTIFS(L_Year,$D$4,L_Month,">="&$H$4,L_Month,"<="&$I$4,L_Type,$B59,L_Act,"تم تحرير مخالفة")) | H59: =IF($B59="","",COUNTIFS(L_Year,$D$4,L_Month,">="&$H$4,L_Month,"<="&$I$4,L_Type,$B59,L_Act,"مشاهدة فقط")) | I59: =IF(OR($B59="",SUM($F$59:$F$68)=0),"",F59/SUM($F$59:$F$68))
B60: =IF(INDEX('الإعدادات'!$L$12:$L$26,2)="","",INDEX('الإعدادات'!$L$12:$L$26,2)) | F60: =IF($B60="","",COUNTIFS(L_Year,$D$4,L_Month,">="&$H$4,L_Month,"<="&$I$4,L_Type,$B60)) | G60: =IF($B60="","",COUNTIFS(L_Year,$D$4,L_Month,">="&$H$4,L_Month,"<="&$I$4,L_Type,$B60,L_Act,"تم تحرير مخالفة")) | H60: =IF($B60="","",COUNTIFS(L_Year,$D$4,L_Month,">="&$H$4,L_Month,"<="&$I$4,L_Type,$B60,L_Act,"مشاهدة فقط")) | I60: =IF(OR($B60="",SUM($F$59:$F$68)=0),"",F60/SUM($F$59:$F$68))
B61: =IF(INDEX('الإعدادات'!$L$12:$L$26,3)="","",INDEX('الإعدادات'!$L$12:$L$26,3)) | F61: =IF($B61="","",COUNTIFS(L_Year,$D$4,L_Month,">="&$H$4,L_Month,"<="&$I$4,L_Type,$B61)) | G61: =IF($B61="","",COUNTIFS(L_Year,$D$4,L_Month,">="&$H$4,L_Month,"<="&$I$4,L_Type,$B61,L_Act,"تم تحرير مخالفة")) | H61: =IF($B61="","",COUNTIFS(L_Year,$D$4,L_Month,">="&$H$4,L_Month,"<="&$I$4,L_Type,$B61,L_Act,"مشاهدة فقط")) | I61: =IF(OR($B61="",SUM($F$59:$F$68)=0),"",F61/SUM($F$59:$F$68))
...

Sheet الإعدادات
A1: الإعدادات والقوائم
A3: اسم المفتش | B3: جاسم الحمادي
A4: الجهة | B4: هيئة البيئة
A5: القطاع | B5: منطقة الظفرة
A6: فولدر الصور (بجانب الملف) | B6: الصور
A9: المواقع حسب المنطقة — لإضافة موقع جديد اكتبه في أول خانة فاضية تحت منطقته، ولإضافة منطقة جديدة اكتب اسمها في خانة عنوان فاضية
A10: الخانات الصفراء فاضية وجاهزة للإضافة
A11: ليوا | B11: حبشان | C11: الرويس | D11: المرفأ | E11: غياثي | F11: السلع | G11: بدع زايد | L11: أنواع المشاهدات | N11: الإجراء | P11: الأشهر | R11: الفترة | S11: من شهر | T11: إلى شهر | V11: اليوم | W11: المناطق المعتادة
A12: الثروانية | B12: حبشان الشرقية | C12: الرويس | D12: المرفأ | E12: غياثي | F12: السلع | G12: بدع زايد | L12: حرق مخلفات | N12: تم تحرير مخالفة | P12: يناير | R12: الربع الأول | S12: 1 | T12: 3 | V12: الاثنين | W12: ليوا (محضر أو محضرين) / المرفأ / الرويس / غياثي / السلع
A13: الجبانة | B13: حبشان الغربية | D13: الطريف | L13: تحميل مياه جوفية في صهاريج | N13: مشاهدة فقط | P13: فبراير | R13: الربع الثاني | S13: 4 | T13: 6 | V13: الثلاثاء | W13: حبشان (شرق أو غرب)
A14: مزيرعة | L14: تصريف / كب صرف صحي | N14: لا يوجد | P14: مارس | R14: النصف الأول | S14: 1 | T14: 6 | V14: الأربعاء | W14: ليوا (محضر أو محضرين) / المرفأ / الرويس / غياثي / السلع
A15: حميم | L15: رمي نفايات عامة | P15: أبريل | R15: الربع الثالث | S15: 7 | T15: 9 | V15: الخميس | W15: حبشان (شرق أو غرب)
A16: بوعوانة | L16: تسرب زيوت أو مواد كيميائية | P16: مايو | R16: الربع الرابع | S16: 10 | T16: 12 | V16: الجمعة | W16: بدع زايد (نصف دوام)
A17: اليارية | L17: حفر آبار غير مصرح | P17: يونيو | R17: النصف الثاني | S17: 7 | T17: 12
A18: موقب | L18: لا توجد مشاهدات | P18: يوليو | R18: التقرير السنوي | S18: 1 | T18: 12
A19: الخيس | P19: أغسطس
A20: نشاش | P20: سبتمبر
A21: وذين | P21: أكتوبر
A22: اليبانة | P22: نوفمبر
A23: يرّة | P23: ديسمبر
A24: موصل
A25: قرمدة
A26: نفير
A27: الرايقة
A28: المارية
A29: المارية الغربية
A30: عتاب
A31: خنّور
A32: الحميضي
A33: الصبخة
A34: حفيف
A35: قطوف
... A44: مهدر بن عصيان
